{
    "registryname": "advanced_alloysmelter",
    "localizedname": "Advanced Alloy Smelting Factory",
    "parts": [
        {
            "x": -1,
            "y": -1,
            "z": 0,
            "elements": "modularmachinery:blockcasing@4"
        },
        {
            "x": 0,
            "y": -1,
            "z": 0,
            "elements": "modularmachinery:blockcasing@2"
        },
        {
            "x": 1,
            "y": -1,
            "z": 0,
            "elements": "modularmachinery:blockcasing@4"
        },
        {
            "x": -1,
            "y": -1,
            "z": 1,
            "elements": "mysticalagriculture:prudentium_furnace"
        },
        {
            "x": 1,
            "y": -1,
            "z": 1,
            "elements": "modularmachinery:blockcasing@2"
        },
        {
            "x": -1,
            "y": -1,
            "z": 2,
            "elements": "modularmachinery:blockcasing@4"
        },
        {
            "x": 1,
            "y": -1,
            "z": 2,
            "elements": [
                "modularmachinery:blockfluidinputhatch@2",
                "modularmachinery:blockfluidinputhatch@3",
                "modularmachinery:blockfluidinputhatch@4",
                "modularmachinery:blockfluidinputhatch@5",
                "modularmachinery:blockfluidinputhatch@6",
                "modularmachinery:blockfluidinputhatch@7"
            ]
        },
        {
            "x": 0,
            "y": -1,
            "z": 2,
            "elements": [
                "modularmachinery:blockenergyinputhatch@2",
                "modularmachinery:blockenergyinputhatch@3",
                "modularmachinery:blockenergyinputhatch@4",
                "modularmachinery:blockenergyinputhatch@5",
                "modularmachinery:blockenergyinputhatch@6",
                "modularmachinery:blockenergyinputhatch@7"
            ]
        },
        {
            "x": 0,
            "y": -1,
            "z": 1,
            "elements": "techreborn:alloy_smelter"
        },


        {
            "x": -1,
            "y": 0,
            "z": 2,
            "elements": "modularmachinery:blockcasing@4"
        },
        {
            "x": 1,
            "y": 0,
            "z": 2,
            "elements": "modularmachinery:blockcasing@4"
        },
        {
            "x": -1,
            "y": 0,
            "z": 0,
            "elements": "modularmachinery:blockcasing@4"
        },
        {
            "x": 1,
            "y": 0,
            "z": 0,
            "elements": "modularmachinery:blockcasing@4"
        },

        {
            "x": 1,
            "y": 0,
            "z": 1,
            "elements": [
                "modularmachinery:blockinputbus@3",
                "modularmachinery:blockinputbus@4",
                "modularmachinery:blockinputbus@5",
                "modularmachinery:blockinputbus@6"
            ]
        },
        {
            "x": -1,
            "y": 0,
            "z": 1,
            "elements": "nuclearcraft:heat_exchanger_frame"
        },
        {
            "x": 0,
            "y": 0,
            "z": 2,
            "elements": "modularmachinery:blockcasing@4"
        },
        {
            "x": 0,
            "y": 0,
            "z": 1,
            "elements": "nuclearcraft:heat_exchanger_frame"
        },


        {
            "x": -1,
            "y": 1,
            "z": 0,
            "elements": "modularmachinery:blockcasing@4"
        },
        {
            "x": 0,
            "y": 1,
            "z": 0,
            "elements": "modularmachinery:blockcasing@2"
        },
        {
            "x": 1,
            "y": 1,
            "z": 0,
            "elements": "modularmachinery:blockcasing@4"
        },
        {
            "x": -1,
            "y": 1,
            "z": 1,
            "elements": "modularmachinery:blockcasing@3"
        },
        {
            "x": 1,
            "y": 1,
            "z": 1,
            "elements": "modularmachinery:blockcasing@2"
        },
        {
            "x": -1,
            "y": 1,
            "z": 2,
            "elements": "modularmachinery:blockcasing@4"
        },
        {
            "x": 1,
            "y": 1,
            "z": 2,
            "elements": "modularmachinery:blockcasing@4"
        },
        {
            "x": 0,
            "y": 1,
            "z": 2,
            "elements": "modularmachinery:blockcasing@4"
        },
        {
            "x": 0,
            "y": 1,
            "z": 1,
            "elements": "actuallyadditions:block_crystal_empowered@5"
        },
        {
            "x": -2,
            "y": 0,
            "z": 2,
            "elements": "modularmachinery:blockcasing@4"
        },
        {
            "x": -2,
            "y": 0,
            "z": 1,
            "elements": [
                "modularmachinery:blockoutputbus@3",
                "modularmachinery:blockoutputbus@4",
                "modularmachinery:blockoutputbus@5",
                "modularmachinery:blockoutputbus@6"
            ]
        },
        {
            "x": -2,
            "y": 0,
            "z": 0,
            "elements": "modularmachinery:blockcasing@4"
        },
        {
            "x": -2,
            "y": -1,
            "z": 2,
            "elements": [
                "modularmachinery:blockfluidinputhatch@2",
                "modularmachinery:blockfluidinputhatch@3",
                "modularmachinery:blockfluidinputhatch@4",
                "modularmachinery:blockfluidinputhatch@5",
                "modularmachinery:blockfluidinputhatch@6",
                "modularmachinery:blockfluidinputhatch@7"
            ]
        },
        {
            "x": -2,
            "y": -1,
            "z": 1,
            "elements": "modularmachinery:blockcasing@2"
        },
        {
            "x": -2,
            "y": -1,
            "z": 0,
            "elements": "modularmachinery:blockcasing@4"
        },
        {
            "x": -2,
            "y": 1,
            "z": 2,
            "elements": "modularmachinery:blockcasing@4"
        },
        {
            "x": -2,
            "y": 1,
            "z": 1,
            "elements": "modularmachinery:blockcasing@2"
        },
        {
            "x": -2,
            "y": 1,
            "z": 0,
            "elements": "modularmachinery:blockcasing@4"
        }
    ]
}